Workbook

Sheet Resumo Executivo
C1: Resumo Executivo
C3: Leitura rápida do cenário ativo, comparação de cenários e checks de integridade. | I3: Versão consultiva v4 | J3: 05/10/2026
B4: USO CONSULTIVO CONTROLADO — não substitui apuração fiscal, parecer tributário ou revisão profissional. | C4: Valores em R$ nominais; altere o seletor na aba Premissas & Cenários.
C6: Painel do cenário ativo
C8: Cenário ativo | D8: ='Premissas & Cenários'!$B$6 | F8: VGV tributável | G8: =Fluxo_Incorporacao!$C$27
C10: Débito IBS + CBS | D10: =Fluxo_Incorporacao!$C$33 | F10: Créditos totais | G10: =Fluxo_Incorporacao!$C$36
C12: Imposto líquido a pagar | D12: =Fluxo_Incorporacao!$C$38 | F12: Lucro líquido | G12: ='DRE Empreendimento'!$E$31
C14: Margem líquida | D14: ='DRE Empreendimento'!$E$32 | F14: Check de integridade | G14: =IF(AND(ROUND(Fluxo_Incorporacao!$C$39,2)=0,ROUND(Fluxo_Incorporacao!$C$112,2)=0,ROUND(Fluxo_Incorporacao!$C$113,2)=0,ROUND('DRE Empreendimento'!$E$33,2)=0,ROUND('DRE Empreendimento'!$E$43,2)=0),"OK","REVISAR")
C16: Status de uso consultivo | D16: ='Matriz Normativa & Governança'!$G$13 | F16: Modo de cálculo | G16: ='Matriz Normativa & Governança'!$C$8
C18: Tributos no ciclo — regime regular | D18: ='Comparativo RET'!$G$13 | F18: Tributos no ciclo — RET (art. 485) | G18: ='Comparativo RET'!$G$19
B19: ="Comparação de cenários — modo: "&'Matriz Normativa & Governança'!$C$8
B20: Indicador | C20: Otimista | D20: Base | E20: Pessimista | F20: Ativo
B21: VGV tributável | C21: ='DRE Empreendimento'!B8 | D21: ='DRE Empreendimento'!C8 | E21: ='DRE Empreendimento'!D8 | F21: ='DRE Empreendimento'!E8
B22: Débito IBS + CBS | C22: ='DRE Empreendimento'!B9 | D22: ='DRE Empreendimento'!C9 | E22: ='DRE Empreendimento'!D9 | F22: ='DRE Empreendimento'!E9
B23: Créditos totais | C23: ='DRE Empreendimento'!B39 | D23: ='DRE Empreendimento'!C39 | E23: ='DRE Empreendimento'!D39 | F23: ='DRE Empreendimento'!E39
B24: Imposto líquido a pagar | C24: ='DRE Empreendimento'!B41 | D24: ='DRE Empreendimento'!C41 | E24: ='DRE Empreendimento'!D41 | F24: ='DRE Empreendimento'!E41
B25: EBITDA | C25: ='DRE Empreendimento'!B23 | D25: ='DRE Empreendimento'!C23 | E25: ='DRE Empreendimento'!D23 | F25: ='DRE Empreendimento'!E23
B26: Lucro líquido | C26: ='DRE Empreendimento'!B31 | D26: ='DRE Empreendimento'!C31 | E26: ='DRE Empreendimento'!D31 | F26: ='DRE Empreendimento'!E31
B27: Margem líquida | C27: ='DRE Empreendimento'!B32 | D27: ='DRE Empreendimento'!C32 | E27: ='DRE Empreendimento'!D32 | F27: ='DRE Empreendimento'!E32
B30: Leitura rápida
B32: O seletor de cenário altera RAJ, participação do Simples, créditos, débito e resultado. O modo padrão é Transição temporal: 2026 com PIS/Cofins e ano-teste dispensado, CBS a partir de 2027 e IBS gradual até 2033.
B34: Crédito de obra por composição do custo (materiais a 27% e serviços de construção terceirizados a 13,5%; folha própria de obra, se houver, sem crédito) e crédito de despesas por categoria; valores com tributo embutido e cálculo por fora.
B36: Os checks de IVA, imposto pago, recebimentos e DRE devem permanecer iguais a zero; “OK” no painel significa que as conexões principais estão fechadas.
B38: Veja a aba Comparativo RET: pelo art. 485, a opção pelo RET antes de 2029 mantém a carga em 4% da receita recebida, sem créditos.
B41: Navegação rápida
B42: Premissas & Cenários
B43: Fluxo_Incorporacao
B44: DRE Empreendimento
B45: Relatório
B47: Módulos consultivos
B48: Transição Tributária
... B53: Comparativo RET

Sheet Premissas & Cenários
A1: Premissas & Cenários
A3: Entradas editáveis, parâmetros tributários, cenários e valores ativos.
A4: Valores monetários em R$ nominais; percentuais em proporção; unidades em quantidade.
A6: Cenário ativo | B6: Pessimista
A8: Premissas operacionais
A10: VGV de lançamento total | B10: 280000000
A11: Permuta física de terreno | B11: 33000000
A12: Número total de unidades | B12: 100
A13: Tipo de imóvel | B13: Residencial Novo
A14: Mês inicial da obra | B14: 2
A15: Mês final da obra | B15: 59
A17: Duração da obra | B17: =B15-B14+1
A18: Prazo total do fluxo | B18: 60
A19: Recebimento de entrada | B19: 0.12
A20: Recebimentos mensais | B20: 0.43
A21: Recebimento nas chaves | B21: 0.45
A22: Total de despesas operacionais e vendas | B22: =SUM(B24:B28)
A24: Projetos e engenharia | B24: 2000000
A25: Marketing e comercialização | B25: 11000000
A26: Comissões de corretagem | B26: 16000000
A27: Administração central | B27: 5000000
A28: Serviços jurídicos e cartórios | B28: 4000000
A31: Premissas tributárias e fiscais
A33: Alíquota padrão combinada IBS + CBS | B33: 0.27
A34: Redução imobiliária | B34: 0.5
A35: Alíquota efetiva plena do setor | B35: =B33*(1-B34)
A36: Alíquota combinada de teste | B36: 0.01
A37: Alíquota efetiva de teste | B37: =B36*(1-B34)
A38: Redutor social residencial novo | B38: 100000
A39: Redutor social lote residencial | B39: 30000
A40: Crédito obra fornecedor regular | B40: 0.27
A41: Crédito obra fornecedor Simples Nacional | B41: 0.04
A42: Fator de crédito serviços intelectuais | B42: 0.7
A43: Crédito de serviços intelectuais | B43: =B40*B42
A44: Base de presunção IRPJ | B44: 0.08
A45: Alíquota IRPJ básica | B45: 0.15
A46: Limite trimestral da base para adicional de IRPJ | B46: 60000
A47: Alíquota IRPJ adicional | B47: 0.1
A48: Base de presunção CSLL | B48: 0.12
A49: Alíquota CSLL | B49: 0.09
...

Sheet Fluxo_Incorporacao
B1: Fluxo_Incorporacao
B3: Cronograma mensal de recebimentos, débito e créditos de IBS + CBS.
B4: Valores em R$ nominais; 60 meses do cronograma financeiro.
B6: Cenário ativo | C6: ='Premissas & Cenários'!$B$6
B8: VGV total | C8: ='Premissas & Cenários'!$G$55
B9: Permuta física | C9: ='Premissas & Cenários'!$G$56
B10: VGV de vendas real tributável | C10: ='Premissas & Cenários'!$G$60
B11: Número total de unidades | C11: ='Premissas & Cenários'!$B$12
B12: Unidades de permuta estimadas | C12: ='Premissas & Cenários'!$G$62
B13: Unidades vendidas tributáveis | C13: ='Premissas & Cenários'!$G$63
B14: RAJ inicial do terreno | C14: ='Premissas & Cenários'!$G$57
B15: Alíquota padrão combinada | C15: ='Premissas & Cenários'!$B$33
B16: Redução imobiliária | C16: ='Premissas & Cenários'!$B$34
B17: Alíquota efetiva plena | C17: ='Premissas & Cenários'!$B$35
B18: Redutor social residencial novo | C18: ='Premissas & Cenários'!$B$38
B19: Redutor social lote residencial | C19: ='Premissas & Cenários'!$B$39
B20: Custo de obra | C20: ='Premissas & Cenários'!$G$58
B21: Participação Simples Nacional | C21: ='Premissas & Cenários'!$G$59
B22: Alíquota média crédito obra | C22: ='Premissas & Cenários'!$G$65
B23: Alíquota média crédito despesas | C23: ='Premissas & Cenários'!$G$66
B26: Memória de cálculo consolidada do IVA
B27: VGV de vendas real tributável | C27: =C10
B28: RAJ efetivo do terreno | C28: =MIN(C27,C14)
B29: Base parcial após RAJ | C29: =MAX(0,C27-C28)
B30: Redutor social total | C30: =MIN(C29,C13*IF('Premissas & Cenários'!$B$13="Residencial Novo",C18,IF('Premissas & Cenários'!$B$13="Lote Residencial",C19,0)))
B31: Base de cálculo tributável final | C31: =MAX(0,C29-C30)
B32: Proporção tributável do preço de venda | C32: =IFERROR(C31/C27,0)
B33: Débito total IBS + CBS (tributo embutido no preço) | C33: =IF('Matriz Normativa & Governança'!$C$8="Alíquota plena — sensibilidade",C31*C17/(1+C17),IF(COUNTIF(P43:P102,"PENDENTE")>0,"",SUM(D43:D102)))
B34: Créditos totais de obra | C34: =SUM(F43:F102)
B35: Créditos totais de despesas | C35: =SUM(H43:H102)
B36: Créditos totais do projeto | C36: =SUM(C34:C35)
B37: Saldo credor final | C37: =IF(C33="","",MAX(0,C36-C33))
B38: Imposto líquido a pagar | C38: =IF(C33="","",MAX(0,C33-C36))
B39: Check IVA | C39: =IF(C33="","",C33-C36-C38+C37)
B40: PIS/Cofins do regime atual (2026, modo transição) | C40: =R103
A41: Cronograma mensal de caixa tributário
A42: Mês | B42: Recebimentos | C42: Base proporcional | D42: Débito IBS + CBS | E42: Custo de obra | F42: Crédito obra | G42: Despesas op. e vendas | H42: Crédito despesas | I42: Saldo credor inicial | J42: Imposto a recolher | K42: Saldo credor final | L42: Imposto pago acumulado | M42: Débito por competência acumulado | N42: Ano | O42: Alíquota consultiva | P42: Status transição | Q42: Fator de crédito do ano | R42: PIS/Cofins regime atual | S42: Trimestre | T42: Débito por R$ recebido | U42: Obra × fator de crédito | V42: Despesas × fator de crédito
A43: 1 | B43: =IF(A43=1,$C$27*'Premissas & Cenários'!$B$19,IF(A43='Premissas & Cenários'!$B$18,$C$27*'Premissas & Cenários'!$B$21,IF(AND(A43>1,A43<'Premissas & Cenários'!$B$18),$C$27*'Premissas & Cenários'!$B$20/'Premissas & Cenários'!$B$17,0))) | C43: =B43*$C$32 | D43: =IF('Matriz Normativa & Governança'!$C$8="Alíquota plena — sensibilidade",C43*$C$17/(1+$C$17),IF(O43="","",C43*O43/(1+O43))) | E43: =IF(AND(A43>='Premissas & Cenários'!$B$14,A43<='Premissas & Cenários'!$B$15),$C$20/'Premissas & Cenários'!$B$17,0) | F43: =E43*$C$22*Q43 | G43: =IFERROR('Premissas & Cenários'!$B$22/'Premissas & Cenários'!$B$18,0) | H43: =G43*$C$23*Q43 | I43: =0 | J43: =MAX(0,D43-F43-H43-I43) | K43: =MAX(0,I43+F43+H43-D43) | L43: =J43 | M43: =SUM($D$43:D43) | N43: =IF(A43<=12,'Premissas & Cenários'!$B$50,IF(A43<=24,'Premissas & Cenários'!$B$50+1,IF(A43<=36,'Premissas & Cenários'!$B$50+2,IF(A43<=48,'Premissas & Cenários'!$B$50+3,'Premissas & Cenários'!$B$50+4)))) | O43: =IFERROR(INDEX('Transição Tributária'!$G$13:$G$20,MATCH(N43,'Transição Tributária'!$A$13:$A$20,0)),"") | P43: =IF(O43="","PENDENTE",IFERROR(INDEX('Transição Tributária'!$I$13:$I$20,MATCH(N43,'Transição Tributária'!$A$13:$A$20,0)),"PENDENTE")) | Q43: =IF('Matriz Normativa & Governança'!$C$8="Alíquota plena — sensibilidade",1,IFERROR(INDEX('Transição Tributária'!$L$13:$L$20,MATCH(N43,'Transição Tributária'!$A$13:$A$20,0)),0)) | R43: =IF('Matriz Normativa & Governança'!$C$8="Alíquota plena — sensibilidade",0,B43*IFERROR(INDEX('Transição Tributária'!$K$13:$K$20,MATCH(N43,'Transição Tributária'!$A$13:$A$20,0)),0)) | S43: =ROUNDUP(A43/3,0) | T43: =IF('Matriz Normativa & Governança'!$C$8="Alíquota plena — sensibilidade",B43*$C$17/(1+$C$17),IF(O43="",0,B43*O43/(1+O43))) | U43: =E43*Q43 | V43: =G43*Q43
A44: 2 | B44: =IF(A44=1,$C$27*'Premissas & Cenários'!$B$19,IF(A44='Premissas & Cenários'!$B$18,$C$27*'Premissas & Cenários'!$B$21,IF(AND(A44>1,A44<'Premissas & Cenários'!$B$18),$C$27*'Premissas & Cenários'!$B$20/'Premissas & Cenários'!$B$17,0))) | C44: =B44*$C$32 | D44: =IF('Matriz Normativa & Governança'!$C$8="Alíquota plena — sensibilidade",C44*$C$17/(1+$C$17),IF(O44="","",C44*O44/(1+O44))) | E44: =IF(AND(A44>='Premissas & Cenários'!$B$14,A44<='Premissas & Cenários'!$B$15),$C$20/'Premissas & Cenários'!$B$17,0) | F44: =E44*$C$22*Q44 | G44: =IFERROR('Premissas & Cenários'!$B$22/'Premissas & Cenários'!$B$18,0) | H44: =G44*$C$23*Q44 | I44: =K43 | J44: =MAX(0,D44-F44-H44-I44) | K44: =MAX(0,I44+F44+H44-D44) | L44: =L43+J44 | M44: =SUM($D$43:D44) | N44: =IF(A44<=12,'Premissas & Cenários'!$B$50,IF(A44<=24,'Premissas & Cenários'!$B$50+1,IF(A44<=36,'Premissas & Cenários'!$B$50+2,IF(A44<=48,'Premissas & Cenários'!$B$50+3,'Premissas & Cenários'!$B$50+4)))) | O44: =IFERROR(INDEX('Transição Tributária'!$G$13:$G$20,MATCH(N44,'Transição Tributária'!$A$13:$A$20,0)),"") | P44: =IF(O44="","PENDENTE",IFERROR(INDEX('Transição Tributária'!$I$13:$I$20,MATCH(N44,'Transição Tributária'!$A$13:$A$20,0)),"PENDENTE")) | Q44: =IF('Matriz Normativa & Governança'!$C$8="Alíquota plena — sensibilidade",1,IFERROR(INDEX('Transição Tributária'!$L$13:$L$20,MATCH(N44,'Transição Tributária'!$A$13:$A$20,0)),0)) | R44: =IF('Matriz Normativa & Governança'!$C$8="Alíquota plena — sensibilidade",0,B44*IFERROR(INDEX('Transição Tributária'!$K$13:$K$20,MATCH(N44,'Transição Tributária'!$A$13:$A$20,0)),0)) | S44: =ROUNDUP(A44/3,0) | T44: =IF('Matriz Normativa & Governança'!$C$8="Alíquota plena — sensibilidade",B44*$C$17/(1+$C$17),IF(O44="",0,B44*O44/(1+O44))) | U44: =E44*Q44 | V44: =G44*Q44
A45: 3 | B45: =IF(A45=1,$C$27*'Premissas & Cenários'!$B$19,IF(A45='Premissas & Cenários'!$B$18,$C$27*'Premissas & Cenários'!$B$21,IF(AND(A45>1,A45<'Premissas & Cenários'!$B$18),$C$27*'Premissas & Cenários'!$B$20/'Premissas & Cenários'!$B$17,0))) | C45: =B45*$C$32 | D45: =IF('Matriz Normativa & Governança'!$C$8="Alíquota plena — sensibilidade",C45*$C$17/(1+$C$17),IF(O45="","",C45*O45/(1+O45))) | E45: =IF(AND(A45>='Premissas & Cenários'!$B$14,A45<='Premissas & Cenários'!$B$15),$C$20/'Premissas & Cenários'!$B$17,0) | F45: =E45*$C$22*Q45 | G45: =IFERROR('Premissas & Cenários'!$B$22/'Premissas & Cenários'!$B$18,0) | H45: =G45*$C$23*Q45 | I45: =K44 | J45: =MAX(0,D45-F45-H45-I45) | K45: =MAX(0,I45+F45+H45-D45) | L45: =L44+J45 | M45: =SUM($D$43:D45) | N45: =IF(A45<=12,'Premissas & Cenários'!$B$50,IF(A45<=24,'Premissas & Cenários'!$B$50+1,IF(A45<=36,'Premissas & Cenários'!$B$50+2,IF(A45<=48,'Premissas & Cenários'!$B$50+3,'Premissas & Cenários'!$B$50+4)))) | O45: =IFERROR(INDEX('Transição Tributária'!$G$13:$G$20,MATCH(N45,'Transição Tributária'!$A$13:$A$20,0)),"") | P45: =IF(O45="","PENDENTE",IFERROR(INDEX('Transição Tributária'!$I$13:$I$20,MATCH(N45,'Transição Tributária'!$A$13:$A$20,0)),"PENDENTE")) | Q45: =IF('Matriz Normativa & Governança'!$C$8="Alíquota plena — sensibilidade",1,IFERROR(INDEX('Transição Tributária'!$L$13:$L$20,MATCH(N45,'Transição Tributária'!$A$13:$A$20,0)),0)) | R45: =IF('Matriz Normativa & Governança'!$C$8="Alíquota plena — sensibilidade",0,B45*IFERROR(INDEX('Transição Tributária'!$K$13:$K$20,MATCH(N45,'Transição Tributária'!$A$13:$A$20,0)),0)) | S45: =ROUNDUP(A45/3,0) | T45: =IF('Matriz Normativa & Governança'!$C$8="Alíquota plena — sensibilidade",B45*$C$17/(1+$C$17),IF(O45="",0,B45*O45/(1+O45))) | U45: =E45*Q45 | V45: =G45*Q45
...

Sheet DRE Empreendimento
B1: DRE Empreendimento
B3: Demonstração do resultado por cenário e DRE ativa anualizada em cinco anos.
B4: Valores em R$ nominais; a coluna de descrição mantém a rastreabilidade às premissas e fundamentos fornecidos.
A6: DRE consolidada por cenário | B6: ="Todas as colunas no modo: "&'Matriz Normativa & Governança'!$C$8&" (selecionado na aba Matriz Normativa & Governança)"
A7: Rubrica | B7: Otimista | C7: Base | D7: Pessimista | E7: Ativo | F7: Descrição de cálculo e fundamentação normativa
A8: Receita bruta — VGV de vendas real | B8: ='Premissas & Cenários'!$B$60 | C8: ='Premissas & Cenários'!$C$60 | D8: ='Premissas & Cenários'!$D$60 | E8: =Fluxo_Incorporacao!$C$27 | F8: VGV de vendas real tributável (VGV menos permuta física, que só é tributada na torna — art. 252, §2º); regime de caixa (art. 262).
A9: Deduções de receita — IBS + CBS (e PIS/Cofins de 2026 no modo transição) | B9: ='Premissas & Cenários'!B68+Fluxo_Incorporacao!$R$103 | C9: ='Premissas & Cenários'!C68+Fluxo_Incorporacao!$R$103 | D9: ='Premissas & Cenários'!D68+Fluxo_Incorporacao!$R$103 | E9: =IF(Fluxo_Incorporacao!$C$33="","",Fluxo_Incorporacao!$C$33+Fluxo_Incorporacao!$R$103) | F9: Débito após RAJ e redutor social (arts. 257 a 260), com tributo embutido no preço; inclui PIS/Cofins de 2026 no modo transição.
A10: Receita operacional líquida | B10: =B8-B9 | C10: =C8-C9 | D10: =D8-D9 | E10: =IF(E9="","",E8-E9) | F10: Receita bruta menos o débito de IBS + CBS sobre vendas.
A11: Custo de obra bruto | B11: ='Premissas & Cenários'!$B$58 | C11: ='Premissas & Cenários'!$C$58 | D11: ='Premissas & Cenários'!$D$58 | E11: =Fluxo_Incorporacao!$C$20 | F11: Custo total de obra informado para o cenário.
A12: Créditos de IBS + CBS sobre construção | B12: ='Premissas & Cenários'!$B$69 | C12: ='Premissas & Cenários'!$C$69 | D12: ='Premissas & Cenários'!$D$69 | E12: =Fluxo_Incorporacao!$C$34 | F12: Crédito por composição do custo: folha sem crédito, materiais à alíquota padrão e serviços de construção à alíquota reduzida (arts. 47 e 261).
A13: Custo do empreendimento líquido | B13: =B11-B12 | C13: =C11-C12 | D13: =D11-D12 | E13: =E11-E12 | F13: Custo de obra bruto menos créditos apropriáveis de construção.
A14: Lucro bruto do projeto | B14: =B10-B13 | C14: =C10-C13 | D14: =D10-D13 | E14: =IF(E10="","",E10-E13) | F14: Receita operacional líquida menos custo do empreendimento líquido.
A16: Projetos e engenharia | B16: ='Premissas & Cenários'!$B$24 | C16: ='Premissas & Cenários'!$B$24 | D16: ='Premissas & Cenários'!$B$24 | E16: =IFERROR(INDEX($B$16:$D$16,1,MATCH(Fluxo_Incorporacao!$C$6,$B$7:$D$7,0)),0) | F16: Despesa informada; profissão intelectual regulamentada, crédito com redução de 30% (art. 127).
A17: Marketing e comercialização | B17: ='Premissas & Cenários'!$B$25 | C17: ='Premissas & Cenários'!$B$25 | D17: ='Premissas & Cenários'!$B$25 | E17: =IFERROR(INDEX($B$17:$D$17,1,MATCH(Fluxo_Incorporacao!$C$6,$B$7:$D$7,0)),0) | F17: Despesa informada; crédito à alíquota padrão sobre a parcela com fornecedor regular.
A18: Comissões de corretagem | B18: ='Premissas & Cenários'!$B$26 | C18: ='Premissas & Cenários'!$B$26 | D18: ='Premissas & Cenários'!$B$26 | E18: =IFERROR(INDEX($B$18:$D$18,1,MATCH(Fluxo_Incorporacao!$C$6,$B$7:$D$7,0)),0) | F18: Despesa informada; intermediação imobiliária com redução de 50% (art. 261).
A19: Administração central | B19: ='Premissas & Cenários'!$B$27 | C19: ='Premissas & Cenários'!$B$27 | D19: ='Premissas & Cenários'!$B$27 | E19: =IFERROR(INDEX($B$19:$D$19,1,MATCH(Fluxo_Incorporacao!$C$6,$B$7:$D$7,0)),0) | F19: Despesa informada; predominantemente folha, crédito só sobre a parcela de serviços de terceiros.
A20: Serviços jurídicos e cartórios | B20: ='Premissas & Cenários'!$B$28 | C20: ='Premissas & Cenários'!$B$28 | D20: ='Premissas & Cenários'!$B$28 | E20: =IFERROR(INDEX($B$20:$D$20,1,MATCH(Fluxo_Incorporacao!$C$6,$B$7:$D$7,0)),0) | F20: Despesa informada; advocacia com redução de 30% (art. 127); validar emolumentos.
A21: Créditos de IBS + CBS sobre despesas | B21: ='Premissas & Cenários'!$B$71 | C21: ='Premissas & Cenários'!$C$71 | D21: ='Premissas & Cenários'!$D$71 | E21: =Fluxo_Incorporacao!$C$35 | F21: Crédito por categoria: alíquota do fornecedor × parcela da base com crédito (Premissas, linhas 97 a 101).
A22: Despesas operacionais e de vendas líquidas | B22: =SUM(B16:B20)-B21 | C22: =SUM(C16:C20)-C21 | D22: =SUM(D16:D20)-D21 | E22: =SUM(E16:E20)-E21 | F22: Despesas brutas menos créditos de IBS + CBS sobre despesas.
A23: EBITDA / resultado operacional | B23: =B14-B22 | C23: =C14-C22 | D23: =D14-D22 | E23: =IF(E14="","",E14-E22) | F23: Lucro bruto do projeto menos despesas operacionais e de vendas líquidas.
A25: Base de presunção IRPJ (com LC 224) | B25: ='IRPJ_CSLL Trimestral'!$I$27 | C25: ='IRPJ_CSLL Trimestral'!$I$27 | D25: ='IRPJ_CSLL Trimestral'!$I$27 | E25: ='IRPJ_CSLL Trimestral'!$I$27 | F25: Soma das bases trimestrais: 8% da receita + 10% de acréscimo sobre o excedente da LC 224.
A26: IRPJ básico | B26: ='IRPJ_CSLL Trimestral'!$J$27 | C26: ='IRPJ_CSLL Trimestral'!$J$27 | D26: ='IRPJ_CSLL Trimestral'!$J$27 | E26: ='IRPJ_CSLL Trimestral'!$J$27 | F26: 15% sobre a base de cada trimestre.
A27: IRPJ adicional | B27: ='IRPJ_CSLL Trimestral'!$K$27 | C27: ='IRPJ_CSLL Trimestral'!$K$27 | D27: ='IRPJ_CSLL Trimestral'!$K$27 | E27: ='IRPJ_CSLL Trimestral'!$K$27 | F27: 10% sobre a base que excede R$ 60 mil por trimestre.
A28: Base de presunção CSLL (com LC 224) | B28: ='IRPJ_CSLL Trimestral'!$L$27 | C28: ='IRPJ_CSLL Trimestral'!$L$27 | D28: ='IRPJ_CSLL Trimestral'!$L$27 | E28: ='IRPJ_CSLL Trimestral'!$L$27 | F28: Soma das bases trimestrais: 12% da receita + 10% de acréscimo sobre o excedente (a partir do 2º tri/2026).
A29: CSLL | B29: ='IRPJ_CSLL Trimestral'!$M$27 | C29: ='IRPJ_CSLL Trimestral'!$M$27 | D29: ='IRPJ_CSLL Trimestral'!$M$27 | E29: ='IRPJ_CSLL Trimestral'!$M$27 | F29: 9% sobre a base de cada trimestre.
A30: Total IRPJ e CSLL | B30: =B26+B27+B29 | C30: =C26+C27+C29 | D30: =D26+D27+D29 | E30: =E26+E27+E29 | F30: Soma do IRPJ básico, IRPJ adicional e CSLL.
A31: Lucro líquido do empreendimento — SPE | B31: =B23-B30 | C31: =C23-C30 | D31: =D23-D30 | E31: =IF(E23="","",E23-E30) | F31: EBITDA menos IRPJ e CSLL.
A32: Margem líquida final | B32: =IFERROR(B31/B8,0) | C32: =IFERROR(C31/C8,0) | D32: =IFERROR(D31/D8,0) | E32: =IFERROR(E31/E8,0) | F32: Lucro líquido dividido pela receita bruta, protegido por IFERROR.
A33: Check DRE | B33: =B10-B13-B22-B30-B31 | C33: =C10-C13-C22-C30-C31 | D33: =D10-D13-D22-D30-D31 | E33: =IF(E10="","",E10-E13-E22-E30-E31) | F33: Receita líquida menos custos líquidos, despesas líquidas, tributos sobre renda e lucro líquido; deve ser zero.
A36: Conta corrente de créditos e liquidação de IVA
A37: Rubrica | B37: Otimista | C37: Base | D37: Pessimista | E37: Ativo | F37: Descrição
A38: Total de débito IBS + CBS | B38: ='Premissas & Cenários'!$B$68 | C38: ='Premissas & Cenários'!$C$68 | D38: ='Premissas & Cenários'!$D$68 | E38: =Fluxo_Incorporacao!$C$33 | F38: Débito total sobre vendas.
A39: Total de créditos: obra + despesas | B39: ='Premissas & Cenários'!$B$72 | C39: ='Premissas & Cenários'!$C$72 | D39: ='Premissas & Cenários'!$D$72 | E39: =Fluxo_Incorporacao!$C$36 | F39: Créditos apropriáveis do projeto.
A40: Saldo líquido do IVA do projeto | B40: =B39-B38 | C40: =C39-C38 | D40: =D39-D38 | E40: =E39-E38 | F40: Créditos menos débitos.
A41: Imposto líquido a pagar | B41: ='Premissas & Cenários'!$B$73 | C41: ='Premissas & Cenários'!$C$73 | D41: ='Premissas & Cenários'!$D$73 | E41: =Fluxo_Incorporacao!$C$38 | F41: Débito menos créditos, limitado a zero.
A42: Saldo credor final | B42: ='Premissas & Cenários'!$B$74 | C42: ='Premissas & Cenários'!$C$74 | D42: ='Premissas & Cenários'!$D$74 | E42: =Fluxo_Incorporacao!$C$37 | F42: Créditos excedentes ao débito.
A43: Check IVA | B43: =B38-B39-B41+B42 | C43: =C38-C39-C41+C42 | D43: =D38-D39-D41+D42 | E43: =IF(E38="","",E38-E39-E41+E42) | F43: Débito menos créditos, imposto a pagar e saldo credor; deve ser zero.
A46: DRE ativa anualizada — cinco anos
A47: Rubrica | B47: ='Premissas & Cenários'!$B$50 | C47: =B47+1 | D47: =C47+1 | E47: =D47+1 | F47: =E47+1 | G47: Total
A48: Receita bruta — recebimentos | B48: =IFERROR(SUMIFS(Fluxo_Incorporacao!$B$43:$B$102,Fluxo_Incorporacao!$N$43:$N$102,B$47),0) | C48: =IFERROR(SUMIFS(Fluxo_Incorporacao!$B$43:$B$102,Fluxo_Incorporacao!$N$43:$N$102,C$47),0) | D48: =IFERROR(SUMIFS(Fluxo_Incorporacao!$B$43:$B$102,Fluxo_Incorporacao!$N$43:$N$102,D$47),0) | E48: =IFERROR(SUMIFS(Fluxo_Incorporacao!$B$43:$B$102,Fluxo_Incorporacao!$N$43:$N$102,E$47),0) | F48: =IFERROR(SUMIFS(Fluxo_Incorporacao!$B$43:$B$102,Fluxo_Incorporacao!$N$43:$N$102,F$47),0) | G48: =SUM(B48:F48)
...

Sheet IRPJ_CSLL Trimestral
B1: IRPJ e CSLL — Lucro Presumido trimestral (LC 224/2025)
B3: Apuração por trimestre sobre a receita recebida, com a majoração da presunção sobre o excedente de R$ 1,25 mi por trimestre (saldo acumulado no ano).
B4: A permuta física sem torna não compõe a receita tributável. A majoração da CSLL vale a partir do 2º trimestre de 2026 (noventena).
A6: Trimestre | B6: Ano | C6: Trimestre no ano | D6: Receita recebida | E6: Receita acumulada no ano | F6: Limite LC 224 acumulado | G6: Excedente acumulado | H6: Excedente do trimestre | I6: Base IRPJ | J6: IRPJ 15% | K6: Adicional IRPJ | L6: Base CSLL | M6: CSLL 9% | N6: Total IRPJ + CSLL
A7: 1 | B7: ='Premissas & Cenários'!$B$50+INT((A7-1)/4) | C7: =MOD(A7-1,4)+1 | D7: =SUMIFS(Fluxo_Incorporacao!$B$43:$B$102,Fluxo_Incorporacao!$S$43:$S$102,A7) | E7: =IF(C7=1,D7,E6+D7) | F7: ='Premissas & Cenários'!$B$106/4*C7 | G7: =IF('Premissas & Cenários'!$B$105="Sim",MAX(0,E7-F7),0) | H7: =IF(C7=1,G7,G7-G6) | I7: =MAX(0,D7*'Premissas & Cenários'!$B$44+H7*'Premissas & Cenários'!$B$44*'Premissas & Cenários'!$B$107) | J7: =I7*'Premissas & Cenários'!$B$45 | K7: =MAX(0,I7-'Premissas & Cenários'!$B$46)*'Premissas & Cenários'!$B$47 | L7: =MAX(0,D7*'Premissas & Cenários'!$B$48+IF(AND(B7=2026,C7=1),0,H7*'Premissas & Cenários'!$B$48*'Premissas & Cenários'!$B$107)) | M7: =L7*'Premissas & Cenários'!$B$49 | N7: =J7+K7+M7
A8: 2 | B8: ='Premissas & Cenários'!$B$50+INT((A8-1)/4) | C8: =MOD(A8-1,4)+1 | D8: =SUMIFS(Fluxo_Incorporacao!$B$43:$B$102,Fluxo_Incorporacao!$S$43:$S$102,A8) | E8: =IF(C8=1,D8,E7+D8) | F8: ='Premissas & Cenários'!$B$106/4*C8 | G8: =IF('Premissas & Cenários'!$B$105="Sim",MAX(0,E8-F8),0) | H8: =IF(C8=1,G8,G8-G7) | I8: =MAX(0,D8*'Premissas & Cenários'!$B$44+H8*'Premissas & Cenários'!$B$44*'Premissas & Cenários'!$B$107) | J8: =I8*'Premissas & Cenários'!$B$45 | K8: =MAX(0,I8-'Premissas & Cenários'!$B$46)*'Premissas & Cenários'!$B$47 | L8: =MAX(0,D8*'Premissas & Cenários'!$B$48+IF(AND(B8=2026,C8=1),0,H8*'Premissas & Cenários'!$B$48*'Premissas & Cenários'!$B$107)) | M8: =L8*'Premissas & Cenários'!$B$49 | N8: =J8+K8+M8
A9: 3 | B9: ='Premissas & Cenários'!$B$50+INT((A9-1)/4) | C9: =MOD(A9-1,4)+1 | D9: =SUMIFS(Fluxo_Incorporacao!$B$43:$B$102,Fluxo_Incorporacao!$S$43:$S$102,A9) | E9: =IF(C9=1,D9,E8+D9) | F9: ='Premissas & Cenários'!$B$106/4*C9 | G9: =IF('Premissas & Cenários'!$B$105="Sim",MAX(0,E9-F9),0) | H9: =IF(C9=1,G9,G9-G8) | I9: =MAX(0,D9*'Premissas & Cenários'!$B$44+H9*'Premissas & Cenários'!$B$44*'Premissas & Cenários'!$B$107) | J9: =I9*'Premissas & Cenários'!$B$45 | K9: =MAX(0,I9-'Premissas & Cenários'!$B$46)*'Premissas & Cenários'!$B$47 | L9: =MAX(0,D9*'Premissas & Cenários'!$B$48+IF(AND(B9=2026,C9=1),0,H9*'Premissas & Cenários'!$B$48*'Premissas & Cenários'!$B$107)) | M9: =L9*'Premissas & Cenários'!$B$49 | N9: =J9+K9+M9
A10: 4 | B10: ='Premissas & Cenários'!$B$50+INT((A10-1)/4) | C10: =MOD(A10-1,4)+1 | D10: =SUMIFS(Fluxo_Incorporacao!$B$43:$B$102,Fluxo_Incorporacao!$S$43:$S$102,A10) | E10: =IF(C10=1,D10,E9+D10) | F10: ='Premissas & Cenários'!$B$106/4*C10 | G10: =IF('Premissas & Cenários'!$B$105="Sim",MAX(0,E10-F10),0) | H10: =IF(C10=1,G10,G10-G9) | I10: =MAX(0,D10*'Premissas & Cenários'!$B$44+H10*'Premissas & Cenários'!$B$44*'Premissas & Cenários'!$B$107) | J10: =I10*'Premissas & Cenários'!$B$45 | K10: =MAX(0,I10-'Premissas & Cenários'!$B$46)*'Premissas & Cenários'!$B$47 | L10: =MAX(0,D10*'Premissas & Cenários'!$B$48+IF(AND(B10=2026,C10=1),0,H10*'Premissas & Cenários'!$B$48*'Premissas & Cenários'!$B$107)) | M10: =L10*'Premissas & Cenários'!$B$49 | N10: =J10+K10+M10
A11: 5 | B11: ='Premissas & Cenários'!$B$50+INT((A11-1)/4) | C11: =MOD(A11-1,4)+1 | D11: =SUMIFS(Fluxo_Incorporacao!$B$43:$B$102,Fluxo_Incorporacao!$S$43:$S$102,A11) | E11: =IF(C11=1,D11,E10+D11) | F11: ='Premissas & Cenários'!$B$106/4*C11 | G11: =IF('Premissas & Cenários'!$B$105="Sim",MAX(0,E11-F11),0) | H11: =IF(C11=1,G11,G11-G10) | I11: =MAX(0,D11*'Premissas & Cenários'!$B$44+H11*'Premissas & Cenários'!$B$44*'Premissas & Cenários'!$B$107) | J11: =I11*'Premissas & Cenários'!$B$45 | K11: =MAX(0,I11-'Premissas & Cenários'!$B$46)*'Premissas & Cenários'!$B$47 | L11: =MAX(0,D11*'Premissas & Cenários'!$B$48+IF(AND(B11=2026,C11=1),0,H11*'Premissas & Cenários'!$B$48*'Premissas & Cenários'!$B$107)) | M11: =L11*'Premissas & Cenários'!$B$49 | N11: =J11+K11+M11
A12: 6 | B12: ='Premissas & Cenários'!$B$50+INT((A12-1)/4) | C12: =MOD(A12-1,4)+1 | D12: =SUMIFS(Fluxo_Incorporacao!$B$43:$B$102,Fluxo_Incorporacao!$S$43:$S$102,A12) | E12: =IF(C12=1,D12,E11+D12) | F12: ='Premissas & Cenários'!$B$106/4*C12 | G12: =IF('Premissas & Cenários'!$B$105="Sim",MAX(0,E12-F12),0) | H12: =IF(C12=1,G12,G12-G11) | I12: =MAX(0,D12*'Premissas & Cenários'!$B$44+H12*'Premissas & Cenários'!$B$44*'Premissas & Cenários'!$B$107) | J12: =I12*'Premissas & Cenários'!$B$45 | K12: =MAX(0,I12-'Premissas & Cenários'!$B$46)*'Premissas & Cenários'!$B$47 | L12: =MAX(0,D12*'Premissas & Cenários'!$B$48+IF(AND(B12=2026,C12=1),0,H12*'Premissas & Cenários'!$B$48*'Premissas & Cenários'!$B$107)) | M12: =L12*'Premissas & Cenários'!$B$49 | N12: =J12+K12+M12
A13: 7 | B13: ='Premissas & Cenários'!$B$50+INT((A13-1)/4) | C13: =MOD(A13-1,4)+1 | D13: =SUMIFS(Fluxo_Incorporacao!$B$43:$B$102,Fluxo_Incorporacao!$S$43:$S$102,A13) | E13: =IF(C13=1,D13,E12+D13) | F13: ='Premissas & Cenários'!$B$106/4*C13 | G13: =IF('Premissas & Cenários'!$B$105="Sim",MAX(0,E13-F13),0) | H13: =IF(C13=1,G13,G13-G12) | I13: =MAX(0,D13*'Premissas & Cenários'!$B$44+H13*'Premissas & Cenários'!$B$44*'Premissas & Cenários'!$B$107) | J13: =I13*'Premissas & Cenários'!$B$45 | K13: =MAX(0,I13-'Premissas & Cenários'!$B$46)*'Premissas & Cenários'!$B$47 | L13: =MAX(0,D13*'Premissas & Cenários'!$B$48+IF(AND(B13=2026,C13=1),0,H13*'Premissas & Cenários'!$B$48*'Premissas & Cenários'!$B$107)) | M13: =L13*'Premissas & Cenários'!$B$49 | N13: =J13+K13+M13
A14: 8 | B14: ='Premissas & Cenários'!$B$50+INT((A14-1)/4) | C14: =MOD(A14-1,4)+1 | D14: =SUMIFS(Fluxo_Incorporacao!$B$43:$B$102,Fluxo_Incorporacao!$S$43:$S$102,A14) | E14: =IF(C14=1,D14,E13+D14) | F14: ='Premissas & Cenários'!$B$106/4*C14 | G14: =IF('Premissas & Cenários'!$B$105="Sim",MAX(0,E14-F14),0) | H14: =IF(C14=1,G14,G14-G13) | I14: =MAX(0,D14*'Premissas & Cenários'!$B$44+H14*'Premissas & Cenários'!$B$44*'Premissas & Cenários'!$B$107) | J14: =I14*'Premissas & Cenários'!$B$45 | K14: =MAX(0,I14-'Premissas & Cenários'!$B$46)*'Premissas & Cenários'!$B$47 | L14: =MAX(0,D14*'Premissas & Cenários'!$B$48+IF(AND(B14=2026,C14=1),0,H14*'Premissas & Cenários'!$B$48*'Premissas & Cenários'!$B$107)) | M14: =L14*'Premissas & Cenários'!$B$49 | N14: =J14+K14+M14
A15: 9 | B15: ='Premissas & Cenários'!$B$50+INT((A15-1)/4) | C15: =MOD(A15-1,4)+1 | D15: =SUMIFS(Fluxo_Incorporacao!$B$43:$B$102,Fluxo_Incorporacao!$S$43:$S$102,A15) | E15: =IF(C15=1,D15,E14+D15) | F15: ='Premissas & Cenários'!$B$106/4*C15 | G15: =IF('Premissas & Cenários'!$B$105="Sim",MAX(0,E15-F15),0) | H15: =IF(C15=1,G15,G15-G14) | I15: =MAX(0,D15*'Premissas & Cenários'!$B$44+H15*'Premissas & Cenários'!$B$44*'Premissas & Cenários'!$B$107) | J15: =I15*'Premissas & Cenários'!$B$45 | K15: =MAX(0,I15-'Premissas & Cenários'!$B$46)*'Premissas & Cenários'!$B$47 | L15: =MAX(0,D15*'Premissas & Cenários'!$B$48+IF(AND(B15=2026,C15=1),0,H15*'Premissas & Cenários'!$B$48*'Premissas & Cenários'!$B$107)) | M15: =L15*'Premissas & Cenários'!$B$49 | N15: =J15+K15+M15
A16: 10 | B16: ='Premissas & Cenários'!$B$50+INT((A16-1)/4) | C16: =MOD(A16-1,4)+1 | D16: =SUMIFS(Fluxo_Incorporacao!$B$43:$B$102,Fluxo_Incorporacao!$S$43:$S$102,A16) | E16: =IF(C16=1,D16,E15+D16) | F16: ='Premissas & Cenários'!$B$106/4*C16 | G16: =IF('Premissas & Cenários'!$B$105="Sim",MAX(0,E16-F16),0) | H16: =IF(C16=1,G16,G16-G15) | I16: =MAX(0,D16*'Premissas & Cenários'!$B$44+H16*'Premissas & Cenários'!$B$44*'Premissas & Cenários'!$B$107) | J16: =I16*'Premissas & Cenários'!$B$45 | K16: =MAX(0,I16-'Premissas & Cenários'!$B$46)*'Premissas & Cenários'!$B$47 | L16: =MAX(0,D16*'Premissas & Cenários'!$B$48+IF(AND(B16=2026,C16=1),0,H16*'Premissas & Cenários'!$B$48*'Premissas & Cenários'!$B$107)) | M16: =L16*'Premissas & Cenários'!$B$49 | N16: =J16+K16+M16
A17: 11 | B17: ='Premissas & Cenários'!$B$50+INT((A17-1)/4) | C17: =MOD(A17-1,4)+1 | D17: =SUMIFS(Fluxo_Incorporacao!$B$43:$B$102,Fluxo_Incorporacao!$S$43:$S$102,A17) | E17: =IF(C17=1,D17,E16+D17) | F17: ='Premissas & Cenários'!$B$106/4*C17 | G17: =IF('Premissas & Cenários'!$B$105="Sim",MAX(0,E17-F17),0) | H17: =IF(C17=1,G17,G17-G16) | I17: =MAX(0,D17*'Premissas & Cenários'!$B$44+H17*'Premissas & Cenários'!$B$44*'Premissas & Cenários'!$B$107) | J17: =I17*'Premissas & Cenários'!$B$45 | K17: =MAX(0,I17-'Premissas & Cenários'!$B$46)*'Premissas & Cenários'!$B$47 | L17: =MAX(0,D17*'Premissas & Cenários'!$B$48+IF(AND(B17=2026,C17=1),0,H17*'Premissas & Cenários'!$B$48*'Premissas & Cenários'!$B$107)) | M17: =L17*'Premissas & Cenários'!$B$49 | N17: =J17+K17+M17
A18: 12 | B18: ='Premissas & Cenários'!$B$50+INT((A18-1)/4) | C18: =MOD(A18-1,4)+1 | D18: =SUMIFS(Fluxo_Incorporacao!$B$43:$B$102,Fluxo_Incorporacao!$S$43:$S$102,A18) | E18: =IF(C18=1,D18,E17+D18) | F18: ='Premissas & Cenários'!$B$106/4*C18 | G18: =IF('Premissas & Cenários'!$B$105="Sim",MAX(0,E18-F18),0) | H18: =IF(C18=1,G18,G18-G17) | I18: =MAX(0,D18*'Premissas & Cenários'!$B$44+H18*'Premissas & Cenários'!$B$44*'Premissas & Cenários'!$B$107) | J18: =I18*'Premissas & Cenários'!$B$45 | K18: =MAX(0,I18-'Premissas & Cenários'!$B$46)*'Premissas & Cenários'!$B$47 | L18: =MAX(0,D18*'Premissas & Cenários'!$B$48+IF(AND(B18=2026,C18=1),0,H18*'Premissas & Cenários'!$B$48*'Premissas & Cenários'!$B$107)) | M18: =L18*'Premissas & Cenários'!$B$49 | N18: =J18+K18+M18
... A26: 20 | B26: ='Premissas & Cenários'!$B$50+INT((A26-1)/4) | C26: =MOD(A26-1,4)+1 | D26: =SUMIFS(Fluxo_Incorporacao!$B$43:$B$102,Fluxo_Incorporacao!$S$43:$S$102,A26) | E26: =IF(C26=1,D26,E25+D26) | F26: ='Premissas & Cenários'!$B$106/4*C26 | G26: =IF('Premissas & Cenários'!$B$105="Sim",MAX(0,E26-F26),0) | H26: =IF(C26=1,G26,G26-G25) | I26: =MAX(0,D26*'Premissas & Cenários'!$B$44+H26*'Premissas & Cenários'!$B$44*'Premissas & Cenários'!$B$107) | J26: =I26*'Premissas & Cenários'!$B$45 | K26: =MAX(0,I26-'Premissas & Cenários'!$B$46)*'Premissas & Cenários'!$B$47 | L26: =MAX(0,D26*'Premissas & Cenários'!$B$48+IF(AND(B26=2026,C26=1),0,H26*'Premissas & Cenários'!$B$48*'Premissas & Cenários'!$B$107)) | M26: =L26*'Premissas & Cenários'!$B$49 | N26: =J26+K26+M26
A27: Total | D27: =SUM(D7:D26) | H27: =SUM(H7:H26) | I27: =SUM(I7:I26) | J27: =SUM(J7:J26) | K27: =SUM(K7:K26) | L27: =SUM(L7:L26) | M27: =SUM(M7:M26) | N27: =SUM(N7:N26)
A28: Check receita | D28: =D27-Fluxo_Incorporacao!$B$103 | E28: Receita trimestral menos recebimentos do fluxo; deve ser zero.

Sheet Comparativo RET
A1: Comparativo — regime regular × RET de transição (art. 485)
A3: Carga tributária do cenário ativo por ano de recebimento. RET: opção efetivada antes de 01/01/2029, com patrimônio de afetação e sem créditos.
A4: =IF('Matriz Normativa & Governança'!$C$8<>"Transição temporal","ATENÇÃO: selecione o modo Transição temporal na aba Matriz Normativa & Governança para este comparativo valer.","Modo Transição temporal ativo: comparativo válido.")
A6: Rubrica | B6: ='Premissas & Cenários'!$B$50+0 | C6: ='Premissas & Cenários'!$B$50+1 | D6: ='Premissas & Cenários'!$B$50+2 | E6: ='Premissas & Cenários'!$B$50+3 | F6: ='Premissas & Cenários'!$B$50+4 | G6: Total | H6: Valor presente
A7: Recebimentos (VGV tributável) | B7: =IFERROR(SUMIFS(Fluxo_Incorporacao!$B$43:$B$102,Fluxo_Incorporacao!$N$43:$N$102,B$6),0) | C7: =IFERROR(SUMIFS(Fluxo_Incorporacao!$B$43:$B$102,Fluxo_Incorporacao!$N$43:$N$102,C$6),0) | D7: =IFERROR(SUMIFS(Fluxo_Incorporacao!$B$43:$B$102,Fluxo_Incorporacao!$N$43:$N$102,D$6),0) | E7: =IFERROR(SUMIFS(Fluxo_Incorporacao!$B$43:$B$102,Fluxo_Incorporacao!$N$43:$N$102,E$6),0) | F7: =IFERROR(SUMIFS(Fluxo_Incorporacao!$B$43:$B$102,Fluxo_Incorporacao!$N$43:$N$102,F$6),0) | G7: =SUM(B7:F7) | H7: =B7/(1+'Premissas & Cenários'!$B$115)^0.5+C7/(1+'Premissas & Cenários'!$B$115)^1.5+D7/(1+'Premissas & Cenários'!$B$115)^2.5+E7/(1+'Premissas & Cenários'!$B$115)^3.5+F7/(1+'Premissas & Cenários'!$B$115)^4.5
A9: A) Regime regular — regime específico de imóveis (LC 214) + Lucro Presumido
A10: PIS/Cofins cumulativo (2026) | B10: =IFERROR(SUMIFS(Fluxo_Incorporacao!$R$43:$R$102,Fluxo_Incorporacao!$N$43:$N$102,B$6),0) | C10: =IFERROR(SUMIFS(Fluxo_Incorporacao!$R$43:$R$102,Fluxo_Incorporacao!$N$43:$N$102,C$6),0) | D10: =IFERROR(SUMIFS(Fluxo_Incorporacao!$R$43:$R$102,Fluxo_Incorporacao!$N$43:$N$102,D$6),0) | E10: =IFERROR(SUMIFS(Fluxo_Incorporacao!$R$43:$R$102,Fluxo_Incorporacao!$N$43:$N$102,E$6),0) | F10: =IFERROR(SUMIFS(Fluxo_Incorporacao!$R$43:$R$102,Fluxo_Incorporacao!$N$43:$N$102,F$6),0) | G10: =SUM(B10:F10) | H10: =B10/(1+'Premissas & Cenários'!$B$115)^0.5+C10/(1+'Premissas & Cenários'!$B$115)^1.5+D10/(1+'Premissas & Cenários'!$B$115)^2.5+E10/(1+'Premissas & Cenários'!$B$115)^3.5+F10/(1+'Premissas & Cenários'!$B$115)^4.5
A11: IBS + CBS recolhido (após créditos) | B11: =IFERROR(SUMIFS(Fluxo_Incorporacao!$J$43:$J$102,Fluxo_Incorporacao!$N$43:$N$102,B$6),0) | C11: =IFERROR(SUMIFS(Fluxo_Incorporacao!$J$43:$J$102,Fluxo_Incorporacao!$N$43:$N$102,C$6),0) | D11: =IFERROR(SUMIFS(Fluxo_Incorporacao!$J$43:$J$102,Fluxo_Incorporacao!$N$43:$N$102,D$6),0) | E11: =IFERROR(SUMIFS(Fluxo_Incorporacao!$J$43:$J$102,Fluxo_Incorporacao!$N$43:$N$102,E$6),0) | F11: =IFERROR(SUMIFS(Fluxo_Incorporacao!$J$43:$J$102,Fluxo_Incorporacao!$N$43:$N$102,F$6),0) | G11: =SUM(B11:F11) | H11: =B11/(1+'Premissas & Cenários'!$B$115)^0.5+C11/(1+'Premissas & Cenários'!$B$115)^1.5+D11/(1+'Premissas & Cenários'!$B$115)^2.5+E11/(1+'Premissas & Cenários'!$B$115)^3.5+F11/(1+'Premissas & Cenários'!$B$115)^4.5
A12: IRPJ + CSLL (trimestral, LC 224) | B12: =IFERROR(SUMIFS('IRPJ_CSLL Trimestral'!$N$7:$N$26,'IRPJ_CSLL Trimestral'!$B$7:$B$26,B$6),0) | C12: =IFERROR(SUMIFS('IRPJ_CSLL Trimestral'!$N$7:$N$26,'IRPJ_CSLL Trimestral'!$B$7:$B$26,C$6),0) | D12: =IFERROR(SUMIFS('IRPJ_CSLL Trimestral'!$N$7:$N$26,'IRPJ_CSLL Trimestral'!$B$7:$B$26,D$6),0) | E12: =IFERROR(SUMIFS('IRPJ_CSLL Trimestral'!$N$7:$N$26,'IRPJ_CSLL Trimestral'!$B$7:$B$26,E$6),0) | F12: =IFERROR(SUMIFS('IRPJ_CSLL Trimestral'!$N$7:$N$26,'IRPJ_CSLL Trimestral'!$B$7:$B$26,F$6),0) | G12: =SUM(B12:F12) | H12: =B12/(1+'Premissas & Cenários'!$B$115)^0.5+C12/(1+'Premissas & Cenários'!$B$115)^1.5+D12/(1+'Premissas & Cenários'!$B$115)^2.5+E12/(1+'Premissas & Cenários'!$B$115)^3.5+F12/(1+'Premissas & Cenários'!$B$115)^4.5
A13: Total — regime regular | B13: =SUM(B10:B12) | C13: =SUM(C10:C12) | D13: =SUM(D10:D12) | E13: =SUM(E10:E12) | F13: =SUM(F10:F12) | G13: =SUM(B13:F13) | H13: =B13/(1+'Premissas & Cenários'!$B$115)^0.5+C13/(1+'Premissas & Cenários'!$B$115)^1.5+D13/(1+'Premissas & Cenários'!$B$115)^2.5+E13/(1+'Premissas & Cenários'!$B$115)^3.5+F13/(1+'Premissas & Cenários'!$B$115)^4.5
A14: % sobre recebimentos | B14: =IFERROR(B13/B7,0) | C14: =IFERROR(C13/C7,0) | D14: =IFERROR(D13/D7,0) | E14: =IFERROR(E13/E7,0) | F14: =IFERROR(F13/F7,0) | G14: =IFERROR(G13/G7,0)
A16: B) RET de transição — art. 485 da LC 214
A17: RET — IRPJ + CSLL | B17: =B7*'Premissas & Cenários'!$B$113 | C17: =C7*'Premissas & Cenários'!$B$113 | D17: =D7*'Premissas & Cenários'!$B$113 | E17: =E7*'Premissas & Cenários'!$B$113 | F17: =F7*'Premissas & Cenários'!$B$113 | G17: =SUM(B17:F17) | H17: =B17/(1+'Premissas & Cenários'!$B$115)^0.5+C17/(1+'Premissas & Cenários'!$B$115)^1.5+D17/(1+'Premissas & Cenários'!$B$115)^2.5+E17/(1+'Premissas & Cenários'!$B$115)^3.5+F17/(1+'Premissas & Cenários'!$B$115)^4.5
A18: RET — PIS/Cofins (2026) e IBS + CBS (2027 em diante) | B18: =B7*'Premissas & Cenários'!$B$114 | C18: =C7*'Premissas & Cenários'!$B$114 | D18: =D7*'Premissas & Cenários'!$B$114 | E18: =E7*'Premissas & Cenários'!$B$114 | F18: =F7*'Premissas & Cenários'!$B$114 | G18: =SUM(B18:F18) | H18: =B18/(1+'Premissas & Cenários'!$B$115)^0.5+C18/(1+'Premissas & Cenários'!$B$115)^1.5+D18/(1+'Premissas & Cenários'!$B$115)^2.5+E18/(1+'Premissas & Cenários'!$B$115)^3.5+F18/(1+'Premissas & Cenários'!$B$115)^4.5
A19: Total — RET | B19: =B17+B18 | C19: =C17+C18 | D19: =D17+D18 | E19: =E17+E18 | F19: =F17+F18 | G19: =SUM(B19:F19) | H19: =B19/(1+'Premissas & Cenários'!$B$115)^0.5+C19/(1+'Premissas & Cenários'!$B$115)^1.5+D19/(1+'Premissas & Cenários'!$B$115)^2.5+E19/(1+'Premissas & Cenários'!$B$115)^3.5+F19/(1+'Premissas & Cenários'!$B$115)^4.5
A20: % sobre recebimentos | B20: =IFERROR(B19/B7,0) | C20: =IFERROR(C19/C7,0) | D20: =IFERROR(D19/D7,0) | E20: =IFERROR(E19/E7,0) | F20: =IFERROR(F19/F7,0) | G20: =IFERROR(G19/G7,0)
A22: Diferença: regime regular − RET (positivo = RET paga menos) | B22: =B13-B19 | C22: =C13-C19 | D22: =D13-D19 | E22: =E13-E19 | F22: =F13-F19 | G22: =SUM(B22:F22) | H22: =B22/(1+'Premissas & Cenários'!$B$115)^0.5+C22/(1+'Premissas & Cenários'!$B$115)^1.5+D22/(1+'Premissas & Cenários'!$B$115)^2.5+E22/(1+'Premissas & Cenários'!$B$115)^3.5+F22/(1+'Premissas & Cenários'!$B$115)^4.5
A23: Regime com menor carga no ciclo | B23: =IF(H22>0,"RET de transição (art. 485)","Regime regular")
A24: Saldo credor de IBS/CBS ao fim do ciclo (regime regular; não incluído acima) | G24: =Fluxo_Incorporacao!$K$102
A26: Notas
A27: • No RET a apropriação de créditos de IBS/CBS é vedada; por isso o custo de obra fica pelo valor bruto e só os tributos pagos são comparados.
A28: • O RET de transição exige patrimônio de afetação e opção efetivada antes de 01/01/2029; incorporação de interesse social: 1% (Premissas, B111).
A29: • O saldo credor do regime regular é ativo a ressarcir: só tem valor se houver ressarcimento ou uso em outras operações da SPE.
A30: • IRPJ/CSLL do regime regular pelo Lucro Presumido; Lucro Real não está modelado.
A31: • Tratamento da permuta física no RET (receita para fins do regime) deve ser validado antes do uso.

Sheet Relatório
A1: Relatório
A3: Relatório de análise contábil-tributária do simulador — versão 4.
A4: Fundamentos normativos listados na Matriz Normativa; validação profissional necessária antes de uso fiscal.
A6: Resultados por cenário
A7: Indicador | B7: Otimista | C7: Base | D7: Pessimista | E7: Ativo | F7: Leitura
A8: RAJ do terreno | B8: ='Premissas & Cenários'!$B$57 | C8: ='Premissas & Cenários'!$C$57 | D8: ='Premissas & Cenários'!$D$57 | E8: =Fluxo_Incorporacao!$C$28 | F8: Maior RAJ reduz a base final de cálculo.
A9: Base tributável final | B9: ='Premissas & Cenários'!$B$67 | C9: ='Premissas & Cenários'!$C$67 | D9: ='Premissas & Cenários'!$D$67 | E9: =Fluxo_Incorporacao!$C$31 | F9: Base após RAJ e redutor social.
A10: Débito total IBS + CBS | B10: ='Premissas & Cenários'!$B$68 | C10: ='Premissas & Cenários'!$C$68 | D10: ='Premissas & Cenários'!$D$68 | E10: =Fluxo_Incorporacao!$C$33 | F10: Débito sobre a base final, no modo de cálculo selecionado.
A11: Créditos totais do projeto | B11: ='Premissas & Cenários'!$B$72 | C11: ='Premissas & Cenários'!$C$72 | D11: ='Premissas & Cenários'!$D$72 | E11: =Fluxo_Incorporacao!$C$36 | F11: Créditos de obra e despesas.
A12: Imposto líquido a pagar | B12: ='Premissas & Cenários'!$B$73 | C12: ='Premissas & Cenários'!$C$73 | D12: ='Premissas & Cenários'!$D$73 | E12: =Fluxo_Incorporacao!$C$38 | F12: Débito menos créditos, limitado a zero.
A13: Saldo credor final | B13: ='Premissas & Cenários'!$B$74 | C13: ='Premissas & Cenários'!$C$74 | D13: ='Premissas & Cenários'!$D$74 | E13: =Fluxo_Incorporacao!$C$37 | F13: Créditos excedentes ao débito.
A14: EBITDA | B14: ='DRE Empreendimento'!B23 | C14: ='DRE Empreendimento'!C23 | D14: ='DRE Empreendimento'!D23 | E14: ='DRE Empreendimento'!E23 | F14: Resultado operacional após créditos de obra e despesas.
A15: Lucro líquido | B15: ='DRE Empreendimento'!B31 | C15: ='DRE Empreendimento'!C31 | D15: ='DRE Empreendimento'!D31 | E15: ='DRE Empreendimento'!E31 | F15: Resultado após IRPJ e CSLL conforme premissas.
A16: Margem líquida | B16: ='DRE Empreendimento'!B32 | C16: ='DRE Empreendimento'!C32 | D16: ='DRE Empreendimento'!D32 | E16: ='DRE Empreendimento'!E32 | F16: Lucro líquido dividido pela receita bruta.
A19: Conclusões da revisão estrutural
A21: A arquitetura tem quatro camadas: premissas, parâmetros ativos, cronograma mensal e demonstrativos. O cenário ativo é escolhido numa única célula com validação de dados.
A22: Crédito de obra: a v3 aplicava 27% sobre todo o custo. A v4 separa materiais (alíquota padrão), serviços de construção terceirizados (alíquota reduzida do art. 261) e eventual folha própria de obra (sem crédito), ponderando fornecedores do Simples.
A23: Valores com tributo embutido: débito e créditos calculados por fora (a ÷ (1 + a)). O cronograma mensal aplica a alíquota de cada ano da transição ao débito e aos créditos.
A24: IRPJ e CSLL apurados por trimestre com a LC 224/2025; a DRE anualizada usa SUMIFS sobre o cronograma e sobre a apuração trimestral.
A25: A aba Comparativo RET mostra a carga do regime regular contra o RET de transição (art. 485). A DRE ganhou a visão societária da permuta física (OCPC 01).
A28: Referências normativas preservadas do material recebido
A30: Art. 13 — alíquota padrão combinada de IBS + CBS (premissa editável).
A31: Art. 47 — créditos de aquisição, ponderados pelo regime do fornecedor.
A32: Art. 127 — redução de 30% para profissões intelectuais regulamentadas (projetos e jurídico).
A33: Arts. 252, §2º; 257 e 258 — permuta (tributa só a torna) e redutor de ajuste do terreno.
A34: Arts. 259 e 260 — redutor social por unidade residencial nova ou lote residencial.
... A36: Arts. 262, 348 e 485 — regime de caixa, ano-teste de 2026 e RET de transição; LC 224/2025 no Lucro Presumido.
A38: Status de uso consultivo | B38: ='Matriz Normativa & Governança'!$G$13 | F38: O gate permanece bloqueado até completar transição, cadastro unitário, documentação de créditos/RAJ e revisão normativa.
A40: Alterações da versão 4
A41: • Crédito de obra por composição de custo (Premissas, linhas 89 a 93).
A42: • Crédito de despesas por categoria, com alíquota do fornecedor e parcela da base com crédito (linhas 97 a 102).
A43: • Débito e créditos por fora, com tributo embutido nos valores informados.
A44: • Tabela de transição 2026-2033 completa e usada como modo padrão; fator de crédito por ano e PIS/Cofins em 2026.
A45: • Nova aba IRPJ_CSLL Trimestral com a majoração da LC 224/2025 (parâmetro para desligar).
A46: • Nova aba Comparativo RET (art. 485).
A47: • Visão societária da permuta física na DRE (OCPC 01) e matriz normativa ampliada.

Sheet Transição Tributária
B1: Transição Tributária
B3: Motor temporal de alíquotas e status de carregamento normativo para o fluxo consultivo.
B4: Percentuais em proporção. CBS e IBS derivam das alíquotas de referência em Premissas; atualizar quando forem fixadas oficialmente.
A6: Regras de uso
A8: Modo consultivo | B8: O fluxo só utiliza esta tabela quando o modo na aba Matriz Normativa & Governança estiver em “Transição temporal”.
A9: Controle | B9: Células com status PENDENTE bloqueiam o status de prontidão para uso fiscal e exigem atualização normativa.
A11: Tabela anual de alíquotas e transição
A12: Ano | B12: CBS base / referência | C12: IBS base / referência | D12: Peso residual ICMS + ISS | E12: Redução imobiliária | F12: Alíquota efetiva setorial | G12: Aplicação no fluxo | H12: Fonte / observação | I12: Status | J12: Recolhimento dispensado? | K12: PIS/Cofins cumulativo (regime atual) | L12: Fator de crédito vs. alíquota plena
A13: 2026 | B13: 0.009 | C13: 0.001 | D13: 0 | E13: ='Premissas & Cenários'!$B$34 | F13: =IF(OR(B13="",C13=""),"",IFERROR((B13+C13)*(1-E13),0)) | G13: =IF(F13="","",IF(J13="Sim",0,F13)) | H13: Ano-teste: CBS 0,9% e IBS 0,1%, dispensados para quem cumpre as obrigações acessórias (ADCT, art. 125, §4º). PIS/Cofins seguem vigentes. | I13: =IF(AND(B13<>"",C13<>""),"OK","PENDENTE") | J13: Sim | K13: ='Premissas & Cenários'!$B$110 | L13: =IF(J13="Sim",0,IFERROR(F13/'Premissas & Cenários'!$B$35,0))
A14: 2027 | B14: ='Premissas & Cenários'!$B$108-0.001 | C14: 0.001 | D14: 0 | E14: ='Premissas & Cenários'!$B$34 | F14: =IF(OR(B14="",C14=""),"",IFERROR((B14+C14)*(1-E14),0)) | G14: =IF(F14="","",IF(J14="Sim",0,F14)) | H14: PIS/Cofins extintos; CBS = referência − 0,1 p.p.; IBS 0,1% (estadual 0,05% + municipal 0,05%). | I14: =IF(AND(B14<>"",C14<>""),"OK","PENDENTE") | J14: Não | K14: 0 | L14: =IF(J14="Sim",0,IFERROR(F14/'Premissas & Cenários'!$B$35,0))
A15: 2028 | B15: ='Premissas & Cenários'!$B$108-0.001 | C15: 0.001 | D15: 0 | E15: ='Premissas & Cenários'!$B$34 | F15: =IF(OR(B15="",C15=""),"",IFERROR((B15+C15)*(1-E15),0)) | G15: =IF(F15="","",IF(J15="Sim",0,F15)) | H15: Mesma regra de 2027. | I15: =IF(AND(B15<>"",C15<>""),"OK","PENDENTE") | J15: Não | K15: 0 | L15: =IF(J15="Sim",0,IFERROR(F15/'Premissas & Cenários'!$B$35,0))
A16: 2029 | B16: ='Premissas & Cenários'!$B$108 | C16: ='Premissas & Cenários'!$B$109*0.1 | D16: 0.9 | E16: ='Premissas & Cenários'!$B$34 | F16: =IF(OR(B16="",C16=""),"",IFERROR((B16+C16)*(1-E16),0)) | G16: =IF(F16="","",IF(J16="Sim",0,F16)) | H16: IBS a 10% da referência; ICMS/ISS a 90% (não incidem na venda de unidade própria). | I16: =IF(AND(B16<>"",C16<>""),"OK","PENDENTE") | J16: Não | K16: 0 | L16: =IF(J16="Sim",0,IFERROR(F16/'Premissas & Cenários'!$B$35,0))
A17: 2030 | B17: ='Premissas & Cenários'!$B$108 | C17: ='Premissas & Cenários'!$B$109*0.2 | D17: 0.8 | E17: ='Premissas & Cenários'!$B$34 | F17: =IF(OR(B17="",C17=""),"",IFERROR((B17+C17)*(1-E17),0)) | G17: =IF(F17="","",IF(J17="Sim",0,F17)) | H17: IBS a 20% da referência. | I17: =IF(AND(B17<>"",C17<>""),"OK","PENDENTE") | J17: Não | K17: 0 | L17: =IF(J17="Sim",0,IFERROR(F17/'Premissas & Cenários'!$B$35,0))
A18: 2031 | B18: ='Premissas & Cenários'!$B$108 | C18: ='Premissas & Cenários'!$B$109*0.3 | D18: 0.7 | E18: ='Premissas & Cenários'!$B$34 | F18: =IF(OR(B18="",C18=""),"",IFERROR((B18+C18)*(1-E18),0)) | G18: =IF(F18="","",IF(J18="Sim",0,F18)) | H18: IBS a 30% da referência. | I18: =IF(AND(B18<>"",C18<>""),"OK","PENDENTE") | J18: Não | K18: 0 | L18: =IF(J18="Sim",0,IFERROR(F18/'Premissas & Cenários'!$B$35,0))
A19: 2032 | B19: ='Premissas & Cenários'!$B$108 | C19: ='Premissas & Cenários'!$B$109*0.4 | D19: 0.6 | E19: ='Premissas & Cenários'!$B$34 | F19: =IF(OR(B19="",C19=""),"",IFERROR((B19+C19)*(1-E19),0)) | G19: =IF(F19="","",IF(J19="Sim",0,F19)) | H19: IBS a 40% da referência. | I19: =IF(AND(B19<>"",C19<>""),"OK","PENDENTE") | J19: Não | K19: 0 | L19: =IF(J19="Sim",0,IFERROR(F19/'Premissas & Cenários'!$B$35,0))
A20: 2033 | B20: ='Premissas & Cenários'!$B$108 | C20: ='Premissas & Cenários'!$B$109 | D20: 0 | E20: ='Premissas & Cenários'!$B$34 | F20: =IF(OR(B20="",C20=""),"",IFERROR((B20+C20)*(1-E20),0)) | G20: =IF(F20="","",IF(J20="Sim",0,F20)) | H20: Vigência integral do novo modelo. | I20: =IF(AND(B20<>"",C20<>""),"OK","PENDENTE") | J20: Não | K20: 0 | L20: =IF(J20="Sim",0,IFERROR(F20/'Premissas & Cenários'!$B$35,0))
A23: Checks da transição
A25: Anos completos | B25: =COUNTIF(I13:I20,"OK") | D25: Anos pendentes | E25: =COUNTIF(I13:I20,"PENDENTE") | G25: Status | H25: =IF(E25=0,"OK","PENDENTE — ATUALIZAR ALÍQUOTAS")

Sheet Cadastro Unidades
B1: Cadastro Unidades
B3: Cadastro unitário para preço, permuta, redutor social, RAJ alocado e documentação.
B4: Valores monetários em R$ nominais; a tabela começa com a premissa média e deve ser substituída pelo cadastro real do empreendimento.
A6: Resumo do cadastro
A8: Total de unidades | B8: =COUNTA(A13:A112) | D8: VGV cadastrado | E8: =SUM(C13:C112) | G8: Unidades tributáveis | H8: =COUNTIF(E13:E112,"Sim")
A9: VGV em permuta | B9: =SUMIFS(C13:C112,D13:D112,"Sim") | D9: VGV tributável | E9: =SUMIFS(C13:C112,E13:E112,"Sim") | G9: Redutor social | H9: =SUM(F13:F112)
A10: RAJ alocado | B10: =SUM(G13:G112) | D10: Check VGV | E10: =E8-'Premissas & Cenários'!$B$10 | G10: Check unidades | H10: =B8-'Premissas & Cenários'!$B$12
A11: Cadastro unitário
A12: ID unidade | B12: Tipo | C12: Preço unitário | D12: Permuta física | E12: Tributável | F12: Redutor social | G12: RAJ alocado | H12: Documento / origem | I12: Status
A13: U001 | B13: Residencial Novo | C13: 2750000 | D13: Sim | E13: =IF(D13="Sim","Não","Sim") | F13: =IF(E13="Sim",IF(B13="Residencial Novo",'Premissas & Cenários'!$B$38,IF(B13="Lote Residencial",'Premissas & Cenários'!$B$39,0)),0) | G13: =IF(E13="Sim",MIN(C13,IFERROR('Premissas & Cenários'!$G$57*C13/SUMIFS($C$13:$C$112,$E$13:$E$112,"Sim"),0)),0) | H13: PENDENTE | I13: =IF(OR(A13="",B13="",C13="",H13="PENDENTE"),"PENDENTE","OK")
A14: U002 | B14: Residencial Novo | C14: 2750000 | D14: Sim | E14: =IF(D14="Sim","Não","Sim") | F14: =IF(E14="Sim",IF(B14="Residencial Novo",'Premissas & Cenários'!$B$38,IF(B14="Lote Residencial",'Premissas & Cenários'!$B$39,0)),0) | G14: =IF(E14="Sim",MIN(C14,IFERROR('Premissas & Cenários'!$G$57*C14/SUMIFS($C$13:$C$112,$E$13:$E$112,"Sim"),0)),0) | H14: PENDENTE | I14: =IF(OR(A14="",B14="",C14="",H14="PENDENTE"),"PENDENTE","OK")
A15: U003 | B15: Residencial Novo | C15: 2750000 | D15: Sim | E15: =IF(D15="Sim","Não","Sim") | F15: =IF(E15="Sim",IF(B15="Residencial Novo",'Premissas & Cenários'!$B$38,IF(B15="Lote Residencial",'Premissas & Cenários'!$B$39,0)),0) | G15: =IF(E15="Sim",MIN(C15,IFERROR('Premissas & Cenários'!$G$57*C15/SUMIFS($C$13:$C$112,$E$13:$E$112,"Sim"),0)),0) | H15: PENDENTE | I15: =IF(OR(A15="",B15="",C15="",H15="PENDENTE"),"PENDENTE","OK")
A16: U004 | B16: Residencial Novo | C16: 2750000 | D16: Sim | E16: =IF(D16="Sim","Não","Sim") | F16: =IF(E16="Sim",IF(B16="Residencial Novo",'Premissas & Cenários'!$B$38,IF(B16="Lote Residencial",'Premissas & Cenários'!$B$39,0)),0) | G16: =IF(E16="Sim",MIN(C16,IFERROR('Premissas & Cenários'!$G$57*C16/SUMIFS($C$13:$C$112,$E$13:$E$112,"Sim"),0)),0) | H16: PENDENTE | I16: =IF(OR(A16="",B16="",C16="",H16="PENDENTE"),"PENDENTE","OK")
A17: U005 | B17: Residencial Novo | C17: 2750000 | D17: Sim | E17: =IF(D17="Sim","Não","Sim") | F17: =IF(E17="Sim",IF(B17="Residencial Novo",'Premissas & Cenários'!$B$38,IF(B17="Lote Residencial",'Premissas & Cenários'!$B$39,0)),0) | G17: =IF(E17="Sim",MIN(C17,IFERROR('Premissas & Cenários'!$G$57*C17/SUMIFS($C$13:$C$112,$E$13:$E$112,"Sim"),0)),0) | H17: PENDENTE | I17: =IF(OR(A17="",B17="",C17="",H17="PENDENTE"),"PENDENTE","OK")
A18: U006 | B18: Residencial Novo | C18: 2750000 | D18: Sim | E18: =IF(D18="Sim","Não","Sim") | F18: =IF(E18="Sim",IF(B18="Residencial Novo",'Premissas & Cenários'!$B$38,IF(B18="Lote Residencial",'Premissas & Cenários'!$B$39,0)),0) | G18: =IF(E18="Sim",MIN(C18,IFERROR('Premissas & Cenários'!$G$57*C18/SUMIFS($C$13:$C$112,$E$13:$E$112,"Sim"),0)),0) | H18: PENDENTE | I18: =IF(OR(A18="",B18="",C18="",H18="PENDENTE"),"PENDENTE","OK")
A19: U007 | B19: Residencial Novo | C19: 2750000 | D19: Sim | E19: =IF(D19="Sim","Não","Sim") | F19: =IF(E19="Sim",IF(B19="Residencial Novo",'Premissas & Cenários'!$B$38,IF(B19="Lote Residencial",'Premissas & Cenários'!$B$39,0)),0) | G19: =IF(E19="Sim",MIN(C19,IFERROR('Premissas & Cenários'!$G$57*C19/SUMIFS($C$13:$C$112,$E$13:$E$112,"Sim"),0)),0) | H19: PENDENTE | I19: =IF(OR(A19="",B19="",C19="",H19="PENDENTE"),"PENDENTE","OK")
A20: U008 | B20: Residencial Novo | C20: 2750000 | D20: Sim | E20: =IF(D20="Sim","Não","Sim") | F20: =IF(E20="Sim",IF(B20="Residencial Novo",'Premissas & Cenários'!$B$38,IF(B20="Lote Residencial",'Premissas & Cenários'!$B$39,0)),0) | G20: =IF(E20="Sim",MIN(C20,IFERROR('Premissas & Cenários'!$G$57*C20/SUMIFS($C$13:$C$112,$E$13:$E$112,"Sim"),0)),0) | H20: PENDENTE | I20: =IF(OR(A20="",B20="",C20="",H20="PENDENTE"),"PENDENTE","OK")
A21: U009 | B21: Residencial Novo | C21: 2750000 | D21: Sim | E21: =IF(D21="Sim","Não","Sim") | F21: =IF(E21="Sim",IF(B21="Residencial Novo",'Premissas & Cenários'!$B$38,IF(B21="Lote Residencial",'Premissas & Cenários'!$B$39,0)),0) | G21: =IF(E21="Sim",MIN(C21,IFERROR('Premissas & Cenários'!$G$57*C21/SUMIFS($C$13:$C$112,$E$13:$E$112,"Sim"),0)),0) | H21: PENDENTE | I21: =IF(OR(A21="",B21="",C21="",H21="PENDENTE"),"PENDENTE","OK")
A22: U010 | B22: Residencial Novo | C22: 2750000 | D22: Sim | E22: =IF(D22="Sim","Não","Sim") | F22: =IF(E22="Sim",IF(B22="Residencial Novo",'Premissas & Cenários'!$B$38,IF(B22="Lote Residencial",'Premissas & Cenários'!$B$39,0)),0) | G22: =IF(E22="Sim",MIN(C22,IFERROR('Premissas & Cenários'!$G$57*C22/SUMIFS($C$13:$C$112,$E$13:$E$112,"Sim"),0)),0) | H22: PENDENTE | I22: =IF(OR(A22="",B22="",C22="",H22="PENDENTE"),"PENDENTE","OK")
A23: U011 | B23: Residencial Novo | C23: 2750000 | D23: Sim | E23: =IF(D23="Sim","Não","Sim") | F23: =IF(E23="Sim",IF(B23="Residencial Novo",'Premissas & Cenários'!$B$38,IF(B23="Lote Residencial",'Premissas & Cenários'!$B$39,0)),0) | G23: =IF(E23="Sim",MIN(C23,IFERROR('Premissas & Cenários'!$G$57*C23/SUMIFS($C$13:$C$112,$E$13:$E$112,"Sim"),0)),0) | H23: PENDENTE | I23: =IF(OR(A23="",B23="",C23="",H23="PENDENTE"),"PENDENTE","OK")
A24: U012 | B24: Residencial Novo | C24: 2750000 | D24: Sim | E24: =IF(D24="Sim","Não","Sim") | F24: =IF(E24="Sim",IF(B24="Residencial Novo",'Premissas & Cenários'!$B$38,IF(B24="Lote Residencial",'Premissas & Cenários'!$B$39,0)),0) | G24: =IF(E24="Sim",MIN(C24,IFERROR('Premissas & Cenários'!$G$57*C24/SUMIFS($C$13:$C$112,$E$13:$E$112,"Sim"),0)),0) | H24: PENDENTE | I24: =IF(OR(A24="",B24="",C24="",H24="PENDENTE"),"PENDENTE","OK")
... A112: U100 | B112: Residencial Novo | C112: 2806818.2 | D112: Não | E112: =IF(D112="Sim","Não","Sim") | F112: =IF(E112="Sim",IF(B112="Residencial Novo",'Premissas & Cenários'!$B$38,IF(B112="Lote Residencial",'Premissas & Cenários'!$B$39,0)),0) | G112: =IF(E112="Sim",MIN(C112,IFERROR('Premissas & Cenários'!$G$57*C112/SUMIFS($C$13:$C$112,$E$13:$E$112,"Sim"),0)),0) | H112: PENDENTE | I112: =IF(OR(A112="",B112="",C112="",H112="PENDENTE"),"PENDENTE","OK")

Sheet Créditos & RAJ
B1: Créditos & RAJ
B3: Registro de créditos por documento e memória de RAJ por ativo, terreno ou matrícula.
B4: Valores monetários em R$ nominais; registros PENDENTE bloqueiam o status de prontidão fiscal.
A6: Resumo de créditos e documentação
A8: Créditos registrados | B8: =SUM(J13:J32) | D8: Base elegível | E8: =SUM(H13:H32) | G8: Registros pendentes | H8: =COUNTIF(K13:K32,"PENDENTE")+COUNTIF(I37:I56,"PENDENTE") | J8: Status documental | K8: =IF(H8=0,"OK","PENDENTE")
A9: Check vs. Premissas | B9: =ROUND(B8-'Premissas & Cenários'!$E$102,2) | D9: Categorias de obra: Materiais, Serviços de construção ou Mão de obra própria. | E9: =B9-'Premissas & Cenários'!$G$57 | G9: Status geral | H9: =IF(AND(K8="OK",ROUND(E9,2)=0),"OK","PENDENTE — REVISAR DOCUMENTOS")
A11: Registro de créditos por documento
A12: ID | B12: Tipo | C12: Categoria | D12: Fornecedor | E12: Regime | F12: Documento fiscal | G12: Competência | H12: Base elegível | I12: Taxa crédito | J12: Crédito calculado | K12: Status documental | L12: Observação
A13: CR001 | B13: Despesa | C13: Projetos e engenharia | D13: PENDENTE | E13: Regular | F13: PENDENTE | G13: PENDENTE | H13: ='Premissas & Cenários'!$B$97*'Premissas & Cenários'!$D$97 | I13: =IFERROR(IF(E13="Simples Nacional",'Premissas & Cenários'!$B$41,IF(C13="Mão de obra própria",0,IF(OR(C13="Serviços de construção",C13="Comissões de corretagem"),'Premissas & Cenários'!$B$40*(1-'Premissas & Cenários'!$B$34),IF(OR(C13="Projetos e engenharia",C13="Serviços jurídicos e cartórios"),'Premissas & Cenários'!$B$43,'Premissas & Cenários'!$B$40)))),0) | J13: =IFERROR(IF(E13="Simples Nacional",H13*I13,H13*I13/(1+I13)),0) | K13: =IF(OR(D13="PENDENTE",F13="PENDENTE",G13="PENDENTE"),"PENDENTE","OK") | L13: Base elegível = valor bruto × parcela com crédito (Premissas). Validar documento, regime e vínculo com o projeto.
A14: CR002 | B14: Despesa | C14: Marketing e comercialização | D14: PENDENTE | E14: Regular | F14: PENDENTE | G14: PENDENTE | H14: ='Premissas & Cenários'!$B$98*'Premissas & Cenários'!$D$98 | I14: =IFERROR(IF(E14="Simples Nacional",'Premissas & Cenários'!$B$41,IF(C14="Mão de obra própria",0,IF(OR(C14="Serviços de construção",C14="Comissões de corretagem"),'Premissas & Cenários'!$B$40*(1-'Premissas & Cenários'!$B$34),IF(OR(C14="Projetos e engenharia",C14="Serviços jurídicos e cartórios"),'Premissas & Cenários'!$B$43,'Premissas & Cenários'!$B$40)))),0) | J14: =IFERROR(IF(E14="Simples Nacional",H14*I14,H14*I14/(1+I14)),0) | K14: =IF(OR(D14="PENDENTE",F14="PENDENTE",G14="PENDENTE"),"PENDENTE","OK") | L14: Crédito indicativo; validar documento, regime, pagamento, vínculo com o projeto e eventual glosa.
A15: CR003 | B15: Despesa | C15: Comissões de corretagem | D15: PENDENTE | E15: Regular | F15: PENDENTE | G15: PENDENTE | H15: ='Premissas & Cenários'!$B$99*'Premissas & Cenários'!$D$99 | I15: =IFERROR(IF(E15="Simples Nacional",'Premissas & Cenários'!$B$41,IF(C15="Mão de obra própria",0,IF(OR(C15="Serviços de construção",C15="Comissões de corretagem"),'Premissas & Cenários'!$B$40*(1-'Premissas & Cenários'!$B$34),IF(OR(C15="Projetos e engenharia",C15="Serviços jurídicos e cartórios"),'Premissas & Cenários'!$B$43,'Premissas & Cenários'!$B$40)))),0) | J15: =IFERROR(IF(E15="Simples Nacional",H15*I15,H15*I15/(1+I15)),0) | K15: =IF(OR(D15="PENDENTE",F15="PENDENTE",G15="PENDENTE"),"PENDENTE","OK") | L15: Crédito indicativo; validar documento, regime, pagamento, vínculo com o projeto e eventual glosa.
